package network.tcp.autocloseable;

public class ResourceCloseMainV3 {

    public static void main(String[] args) {
        try {
            logic();
        } catch (CallException e) {
            System.out.println("CallException 예외 처리");
            e.printStackTrace();
        } catch (CloseException e) {
            System.out.println("CloseException 예외 처리");
            e.printStackTrace();
        }
    }

    private static void logic() throws CallException, CloseException {
        ResourceV1 resource1 = null;
        ResourceV1 resource2 = null;

        try {
            resource1 = new ResourceV1("resource1");
            resource2 = new ResourceV1("resource2");

            resource1.call();
            resource2.callEx();
        } catch (CallException e) {
            System.out.println("ex: " + e);
            throw e; // CallException 다시 던짐
        } finally {
            if (resource2 != null) {
                try {
                    resource2.closeEx(); // close하려는데 예외 발생한 상황
                } catch (CloseException e) {
                    // close() 과정에서 발생한 부가적인 예외인 CloseException은 버림. 핵심 예외는 CallException.
                    System.out.println("close ex: " + e);
                }
            }
            if (resource1 != null) {
                try {
                    resource1.closeEx();
                } catch (CloseException e) {
                    System.out.println("close ex: " + e);
                }
            }
        }
    }
}
